Workbook

Sheet 表紙
G11: =MID(CELL("filename",A1),FIND("[",CELL("filename",A1))+1,FIND("]",CELL("filename",A1))-FIND("[",CELL("filename",A1))-1) -> 29-2業務フロー.xlsx
G12: =FIND("_",G11,20) -> #VALUE! | H12: =MID(G11,G12+1,6) -> #VALUE! | K12: =SUBSTITUTE(MID(G11,G12+8,100),".xlsx","") -> #VALUE!
G13: =H12&"（"&K12&"）" -> #VALUE!
R23: ="第"&IFERROR(INDEX(version!F8:F200,COUNTA(version!F8:F200)+0),"")&"版" -> 第0.2版
N25: =version!AF4 -> 45243

Sheet version
A1: プロジェクト名 | E1: Biz-X POTTS | I1: 資料分類 | M1: 要件定義 | Q1: 資料小分類 | AB1: 作成 | AD1: 担当
AD2: 日付 | AF2: 45243
A3: システム名 | I3: 成果物ID | Q3: ― | U3: ― | AB3: 修正 | AD3: 担当 | AF3: =IFERROR(INDEX(I8:I200,COUNTA(I8:I200)+0),"")
AD4: 日付 | AF4: 45243
B7: 更新日 | F7: Ver | I7: 更新者 | M7: 更新箇所（シート） | R7: 更新内容
B8: 45243 | F8: 0.1 | M8: すべて | R8: 新規作成
B9: 45254 | F9: 0.2 | M9: フロー-運営管理 | R9: 申込機能のデータを更新

Sheet ガイド
A1: １．概要
B3: 一連の業務の流れ（ビジネスプロセス）を、システム機能と主要なデータを紐付けて可視化する。
A5: ２．使途
B7: ● システム化対象範囲のシステム機能が網羅的に機能一覧に抽出できていること、妥当なシステム機能として定義されていることを確認する。
A9: ３．記入要領
B11: 業務一覧上の大分類毎にシートを分ける。
B14: (1) フロー概要
B16: 各ユースケース内におけるフロー名およびフロー概要について記載する。
B17: １ユースケースにおいて、複数のフローに分かれる場合は、それぞれのフローについて記載する。
B19: No | C19: 記述内容 | I19: 記述内容説明 | Z19: 補足
B20: 1 | C20: No | I20: ユースケース内の各フローの連番を記載する。
B21: =B20+1 -> 2 | C21: 業務内容 | I21: フロー名称を記載する。
B22: =B21+1 -> 3 | C22: 業務概要 | I22: フローの業務概要を記載する。
B25: (2) フロー
B28: No | C28: 記述内容 | I28: 記述内容説明 | Z28: 補足
B29: 1 | C29: 業務内容 | I29: フロー名称を記載する。
B30: 2 | C30: タイミング | I30: 業務および処理が発生するタイミングを記載する。 （随時、日次、２分間隔など）
B31: 3 | C31: 基幹系システム | I31: 基幹系システムについてを記載する。
B32: 4 | C32: admin | I32: admin管理者の処理を記述する。
B33: 5 | C33: お客様 | I33: 会社管理者/使用者の処理を記述する。
B34: 6 | C34: ソロアリ
D35: フロント | I35: フロント機能の処理を記述する。
B36: 7 | D36: 場所 | I36: 場所のデータて記載する。
B37: 8 | D37: 外部システム | I37: 対象範囲外のシステムに関する処理を記載する。
B38: 9 | D38: データ | I38: 主要なデータについて記載する。
B39: No | C39: 記述内容 | I39: 記述内容説明 | X39: 表記例 | AB39: 補足
B40: 1 | C40: 処理Ｎｏ | I40: ユースケース内において、フロント画面処理→バッチ処理等の非同期処理が発生する場合、フローを分けて記載し、連続性が分かるよう処理Ｎｏを記述する。
B41: =B40+1 -> 2 | C41: アクター
D42: お客様 | I42: 申込者の際に記載する。
B43: =B41+1 -> 3 | D43: admin | I43: admin管理者の業務が発生する際に記載する。
B44: =B43+1 -> 4 | D44: 会社管理者/使用者 | I44: 会社管理者/使用者の業務が発生する際に記載する。
B45: =B44+1 -> 5 | C45: フロント画面 | I45: フロント機能の処理を大項目レベル(ID、名称)で記載する。
B46: 6 | C46: バッチ | I46: バッチ機能の処理を大項目レベル(ID、名称)で記載する。
B47: =B46+1 -> 7 | C47: API | I47: API機能の処理を記載する。APIのIDと名称をともに記載する。 APIのIDが未確定の場合は「XXXXX」を記載する。
B48: =B47+1 -> 8 | C48: 外部システム | I48: 外部システムの処理を記載する。処理のIDと名称をともに記載する。 IDが未確定の場合は処理名称のみを記載する。
B49: =B48+1 -> 9 | C49: データ | I49: アクセスされるDB上のデータについて記載する。
B50: =B49+1 -> 10 | C50: メール | I50: メール情報を記載。メールＩＤ，メール名称ともに記載する。 メールＩＤが未確定の場合は「XXXXX」を記載する。
B51: =B50+1 -> 11 | C51: ファイル | I51: 作成ファイル等を記載する。
B52: =B51+1 -> 12 | C52: 分岐 | I52: 条件によって、フローが分岐する際に記載する。 分岐の条件等を記載する。

Sheet フロー-入荷
A1: PJ名 | M1: =version!E1 -> Biz-X POTTS | N1: =#REF! -> #REF! | O1: =#REF! -> #REF! | P1: =#REF! -> #REF! | Q1: =#REF! -> #REF! | R1: =#REF! -> #REF! | S1: =#REF! -> #REF! | T1: =#REF! -> #REF! | U1: =#REF! -> #REF! | ... AB1: =#REF! -> #REF! | AC1: 工程 | AK1: 要件定義 | CC1: =MID(CELL("filename",$A$1),FIND("]",CELL("filename",$A$1))+1,31) -> フロー-入荷
A2: ユースケースID | AC2: ユースケース名称 | AK2: フロー-入荷
B4: No | G4: 業務内容 | AE4: 業務概要
B6: =ROW()-5 -> 1 | G6: ■入荷予定入力 | AE6: ・入荷情報手動入力画面 ・入荷予定CSVを読み込み、入荷予定トランにinsertする
B7: =ROW()-5 -> 2 | G7: ■入荷予定照会 | AE7: ・入荷予定トランの画面照会 ・入荷予定トランの一覧出力 ・入荷予定トランの削除
B8: =ROW()-5 -> 3 | G8: ■入荷検品 | AE8: ・入荷予定一覧バーコードをスキャンして入荷商品の検品
B9: =ROW()-5 -> 4 | G9: ■入庫入力 | AE9: ・在庫トランの登録・修正・削除
B10: =ROW()-5 -> 5 | G10: ■入庫照会 | AE10: ・在庫トランの画面照会 ・在庫トランの一覧出力
B11: =ROW()-5 -> 6 | G11: ■入荷確定 | AE11: ・入荷予定トランの画面照会 ・入荷予定トランの一覧出力 ・入荷データの確定とキャンセル
B12: =ROW()-5 -> 7 | G12: ■入荷確定データ出力 | AE12: ・入荷確定CSVを出力
B15: 業務内容 | N15: ﾀｲﾐﾝｸﾞ | R15: 基幹系システム | AV15: admin | BJ15: お客様 | BZ15: ソロアリ | FC15: 備考
BZ16: フロント１ | CR16: フロント２ | DG16: 場所 | EC16: データ
B17: ■入荷予定入力 | N17: 随時
CD21: 手動登録・更新
CJ28: 登録/修正
B30: ■入荷予定照会 | N30: 随時 | CN30: 画面検索データ
CN32: 入荷予定削除
CJ34: 一覧出力
B40: ■入荷検品 | N40: 随時 | CN40: 検品
CJ44: 商品ラベル出力
CP49: バーコードを読み込み
CG50: バーコードを読み込み
B53: ■入庫入力 | N53: 随時
CN54: データ検索
CN56: 商品情報を入力
CJ59: 在庫サマリ登録・修正・削除
CG61: 商品ラベル出力
CJ66: 入庫入力遷移
B67: ■入庫照会 | N67: 随時
CJ72: 一覧出力
B81: ■入荷確定 | N81: 随時 | CN81: 画面検索データ
CN83: 画面データ更新
CJ85: 一覧出力
B92: ■入荷確定データ出力
N93: 随時
CJ97: 入荷確定CSVを出力
AD99: 基幹系システム取得

Sheet フロー-出荷
A1: PJ名 | M1: =version!E1 -> Biz-X POTTS | N1: =#REF! -> #REF! | O1: =#REF! -> #REF! | P1: =#REF! -> #REF! | Q1: =#REF! -> #REF! | R1: =#REF! -> #REF! | S1: =#REF! -> #REF! | T1: =#REF! -> #REF! | U1: =#REF! -> #REF! | ... AB1: =#REF! -> #REF! | AC1: 工程 | AK1: 要件定義 | CC1: =MID(CELL("filename",$A$1),FIND("]",CELL("filename",$A$1))+1,31) -> フロー-出荷
A2: ユースケースID | AC2: ユースケース名称 | AK2: フロー-出荷
B4: No | G4: 業務内容 | AE4: 業務概要
B6: =ROW()-5 -> 1 | G6: ■出荷指示入力 | AE6: ・出荷情報手動入力画面 ・出荷指示CSVを読み込み、出荷指示トランにinsertする
B7: =ROW()-5 -> 2 | G7: ■出荷指示照会 | AE7: ・出荷指示トランの画面照会 ・出荷指示トランの一覧出力 ・出荷指示トランの削除 ・引当処理
B8: =ROW()-5 -> 3 | G8: ■欠品伝票照会 | AE8: ・欠品のデータの画面照会 ・引当処理
B9: =ROW()-5 -> 4 | G9: ■ピッキングリスト（シングル） | AE9: ・ピッキングリスト（シングル）画面照会 ・ピッキングリスト（シングル）一覧出力
B10: =ROW()-5 -> 5 | G10: ■出庫入力 | AE10: ・出庫情報の登録・修正・削除
B11: =ROW()-5 -> 6 | G11: ■出庫照会 | AE11: ・出庫情報の画面照会 ・出庫情報の一覧出力
B12: =ROW()-5 -> 7 | G12: ■納品書 | AE12: ・納品書情報を出力
B13: =ROW()-5 -> 8 | G13: ■出荷検品 | AE13: ・納品書のバーコードをスキャンして出荷商品の検品
B14: =ROW()-5 -> 9 | G14: ■出荷確定 | AE14: ・出荷指示トランの画面照会 ・出荷指示トランの一覧出力 ・出荷データの確定とキャンセル
B15: =ROW()-5 -> 10 | G15: ■出荷確定データ出力 | AE15: ・出荷確定CSVを出力
B18: 業務内容 | N18: ﾀｲﾐﾝｸﾞ | R18: 基幹系システム | AV18: admin | BJ18: お客様 | BZ18: ソロアリ | FC18: 備考
BZ19: フロント１ | CR19: フロント２ | DG19: 場所 | EC19: データ
B20: ■出荷指示入力 | N20: 随時
CD24: 手動登録・更新
CJ31: 登録/修正
B33: ■出荷指示照会 | N33: 随時 | CN33: 画面検索データ
CN35: 出荷指示削除
DI38: 成功の場合
CJ40: 一覧出力
CW42: 失敗の場合
B47: ■欠品伝票照会 | N47: 随時 | CN47: 画面検索データ
CM52: 引当処理、成功の場合
B57: ■ピッキングリスト（シングル） | CN57: 画面検索データ
N58: 随時
CK61: 一覧出力
CP66: バーコードを読み込み
CP69: バーコードを読み込み
CG72: バーコードを読み込み
B73: ■出庫入力 | N73: 随時
CN74: データ検索
CL79: 出庫入力実施
CG81: 商品ラベル出力
CJ86: 出庫入力遷移
B87: ■出庫照会 | N87: 随時
CN88: データ検索
CJ92: 一覧出力
B98: ■納品書 | N98: 随時 | CN98: データ検索
...

Sheet フロー-棚卸
A1: PJ名 | M1: =version!E1 -> Biz-X POTTS | N1: =#REF! -> #REF! | O1: =#REF! -> #REF! | P1: =#REF! -> #REF! | Q1: =#REF! -> #REF! | R1: =#REF! -> #REF! | S1: =#REF! -> #REF! | T1: =#REF! -> #REF! | U1: =#REF! -> #REF! | ... AB1: =#REF! -> #REF! | AC1: 工程 | AK1: 要件定義 | CC1: =MID(CELL("filename",$A$1),FIND("]",CELL("filename",$A$1))+1,31) -> フロー-棚卸
A2: ユースケースID | AC2: ユースケース名称 | AK2: フロー-棚卸
B4: No | G4: 業務内容 | AE4: 業務概要
B6: =ROW()-5 -> 1 | G6: ■棚卸開始 | AE6: ・棚卸開始画面
B7: =ROW()-5 -> 2 | G7: ■実棚明細入力 | AE7: ・実棚明細情報の登録 ・実棚明細情報の修正
B8: =ROW()-5 -> 3 | G8: ■棚卸照会 | AE8: ・棚卸トランの画面照会 ・棚卸トランの削除 ・棚卸トランの一覧出力
B9: =ROW()-5 -> 4 | G9: ■棚卸確定 | AE9: ・棚卸結果の照会と確定とキャンセル
B10: =ROW()-5 -> 5 | G10: ■棚卸データ出力 | AE10: ・棚卸確定CSVを出力
B13: 業務内容 | N13: ﾀｲﾐﾝｸﾞ | R13: 基幹系システム | AV13: admin | BJ13: お客様 | BZ13: ソロアリ | FC13: 備考
BZ14: フロント１ | CR14: フロント２ | DG14: 場所 | EC14: データ
B15: ■棚卸開始 | N15: 随時
CO19: チェックOKの場合、DBを更新する
B24: ■実棚明細入力 | N24: 随時 | CO24: 登録と修正
CB28: 棚卸開始 | CJ28: 実棚明細入力/修正
B31: ■棚卸照会 | N31: 随時 | CN31: 画面検索データ
CN33: 棚卸削除
CJ35: 一覧出力
B41: ■棚卸確定 | N41: 随時 | CN41: 画面検索データ
CK46: 確定・キャンセル
B52: ■棚卸データ出力
N53: 随時
CJ57: 棚卸確定CSVを出力
AD59: 基幹系システム取得

Sheet フロー-在庫
A1: PJ名 | M1: =version!E1 -> Biz-X POTTS | N1: =#REF! -> #REF! | O1: =#REF! -> #REF! | P1: =#REF! -> #REF! | Q1: =#REF! -> #REF! | R1: =#REF! -> #REF! | S1: =#REF! -> #REF! | T1: =#REF! -> #REF! | U1: =#REF! -> #REF! | ... AB1: =#REF! -> #REF! | AC1: 工程 | AK1: 要件定義 | CC1: =MID(CELL("filename",$A$1),FIND("]",CELL("filename",$A$1))+1,31) -> フロー-在庫
A2: ユースケースID | AC2: ユースケース名称 | AK2: フロー-在庫
B4: No | G4: 業務内容 | AE4: 業務概要
B6: =ROW()-5 -> 1 | G6: ■在庫照会 | AE6: ・在庫トランの画面照会 ・在庫CSVを読み込み、在庫トランにinsertする ・在庫トランの一覧出力
B7: =ROW()-5 -> 2 | G7: ■受払照会 | AE7: ・受払トランの画面照会 ・受払トランの一覧出力
B8: =ROW()-5 -> 3 | G8: ■返品入力 | AE8: ・売上返品の入力処理 ・仕入返品の入力処理
B9: =ROW()-5 -> 4 | G9: ■返品照会 | AE9: ・返品トランの画面照会 ・返品トランの削除
B10: =ROW()-5 -> 5 | G10: ■在庫移動入力 | AE10: ・在庫情報の移動処理
B11: =ROW()-5 -> 6 | G11: ■在庫移動照会 | AE11: ・在庫移動トランの画面照会 ・在庫移動トランの一覧出力
B12: =ROW()-5 -> 7 | G12: ■在庫調整入力 | AE12: ・在庫情報の調整処理
B13: =ROW()-5 -> 8 | G13: ■在庫調整照会 | AE13: ・在庫調整トランの画面照会 ・在庫調整トランの一覧出力
B16: 業務内容 | N16: ﾀｲﾐﾝｸﾞ | R16: 基幹系システム | AV16: admin | BJ16: お客様 | BZ16: ソロアリ | FC16: 備考
BZ17: フロント１ | CR17: フロント２ | DG17: 場所 | EC17: データ
B18: ■在庫照会 | N18: 随時
CO25: 検索データ
BN28: 在庫CSV取込
CJ29: 一覧出力
B36: ■受払照会 | N36: 随時
CK40: 一覧出力
B46: ■返品入力 | N46: 随時 | CO46: 入出荷情報検索
CJ50: 返品
CN52: 売上返品 | CV52: 在庫数追加
CN56: 仕入返品 | CV56: 在庫数削減
B60: ■返品照会 | N60: 随時 | CO60: 検索データ
CJ64: 返品削除
CN66: 売上返品 | CV66: 在庫数削減
CN70: 仕入返品 | CV70: 在庫数追加
CO73: 検索データ
B74: ■在庫移動入力 | N74: 随時
CK78: 移動データ更新
B84: ■在庫移動照会 | N84: 随時 | CO84: 検索データ
CK88: 一覧出力
B95: ■在庫調整入力 | N95: 随時 | CO95: 検索データ
CL99: 調整データ更新
B105: ■在庫調整照会 | N105: 随時
CK109: 一覧出力

Sheet フロー-運営管理
A1: PJ名 | M1: =version!E1 -> Biz-X POTTS | N1: =#REF! -> #REF! | O1: =#REF! -> #REF! | P1: =#REF! -> #REF! | Q1: =#REF! -> #REF! | R1: =#REF! -> #REF! | S1: =#REF! -> #REF! | T1: =#REF! -> #REF! | U1: =#REF! -> #REF! | ... AB1: =#REF! -> #REF! | AC1: 工程 | AK1: 要件定義 | CC1: =MID(CELL("filename",$A$1),FIND("]",CELL("filename",$A$1))+1,31) -> フロー-運営管理
A2: ユースケースID | AC2: ユースケース名称 | AK2: フロー-運営管理
B4: No | G4: 業務内容 | AE4: 業務概要
B6: =ROW()-5 -> 1 | G6: ■課金法人管理 | AE6: ・運用会社情報の画面照会 ・運用会社情報の登録と修正
B7: =ROW()-5 -> 2 | G7: ■ライセンス管理 | AE7: ・ライセンス情報の画面照会 ・ライセンス情報の登録と修正
B8: =ROW()-5 -> 3 | G8: ■ユーザーライセンス管理 | AE8: ・ユーザー情報の画面照会 ・ユーザー情報の登録と修正 ・ユーザーライセンス情報の画面照会 ・ユーザーライセンス情報の登録と修正
B9: =ROW()-5 -> 4 | G9: ■メッセージ管理 | AE9: ・運用メッセージマスタ（社内メッセージマスタ）情報の画面照会 ・運用メッセージマスタ（社内メッセージマスタ）情報の登録と修正と削除 ・運用メッセージマスタ（社内メッセージマスタ）情報の送信
B10: =ROW()-5 -> 5 | G10: ■申込機能 | AE10: ・申込ページより申し込み ・決済、自動メール発送 ・申込受付 ・企業側作業：マスタ設定、アカウント追加
B11: =ROW()-5 -> 6 | G11: ■自動応答 | AE11: ・ライセンスの自動更新 ・ライセンス変更時の応答
B12: =ROW()-5 -> 7 | G12: ■解約機能 | AE12: ・解約申請ページより解約申請 ・自動応答メール送信 ・解約ページを起動 ・解約確定実行 ・ライセンス期間の期日到来で該当企業の環境削除
B15: 業務内容 | N15: ﾀｲﾐﾝｸﾞ | R15: 基幹系システム | AV15: admin | BJ15: お客様 | BZ15: ソロアリ | FC15: 備考
BZ16: フロント１ | CR16: フロント２ | DG16: 外部システム | EC16: データ
B17: ■課金法人管理 | N17: 随時
CN19: 検索データ
CN21: 登録/修正
CN25: 検索データ
B26: ■ライセンス管理 | N26: 随時
CN27: 登録/修正
CN30: 検索データ
B32: ■ユーザーライセンス管理
N33: 随時
CK35: ライセンス
DI36: 検索データ
DI37: 登録/修正
B40: ■メッセージ管理 | N40: 随時 | CN40: 検索データ
CN43: 登録/修正/削除
CJ45: 送信
DI51: 選択のユーザーを送信
CO56: 申込情報保存
B57: ■申込機能 | N57: 随時
CJ62: 決済
CH67: メール発送
CO73: 受付データ更新
CB77: 受付結果に知らせる
B88: ■自動応答 | N88: 随時
B94: ■解約機能 | N94: 随時 | CN94: 検索データ
CI98: 管理者確認
