Workbook

Sheet 変更履歴
A1: ドキュメントID | J1: ドキュメント名称 | AU1: 作成日 | AZ1: 更新日 | BE1: 更新者 | BK1: ﾊﾞｰｼﾞｮﾝ
J2: マスタコード体系／一覧 | AU2: =MIN(B$7:B$27) -> 45518 | AZ2: =IF(COUNTA(B7:B27)>1,MAX(B$7:B$27),"") | BE2: =VLOOKUP(MAX($B$7:$B27),$B$7:$L27,6,FALSE) -> 穆政道 | BK2: =MAX(M$7:M$27) -> 1
B4: 変更履歴
B6: 日付 | G6: 作成/変更者 | M6: ﾊﾞｰｼﾞｮﾝ | R6: 概要（対象、修正内容 等） | AW6: 補足
A7: ■■ | B7: 45518 | G7: 穆政道 | M7: 1 | R7: 作成
A8: ■■
A9: ■■
A10: ■■
A11: ■■
A12: ■■
A13: ■■
A14: ■■
A15: ■■
A16: ■■
A17: ■■
A18: ■■
A19: ■■
... A27: ■■

Sheet コードグループ一覧
A1: ドキュメントID | N1: ドキュメント名称 | BS1: 作成日 | BX1: 更新日 | CC1: 更新者 | CI1: ﾊﾞｰｼﾞｮﾝ
A2: =変更履歴!$A$2 -> 0 | N2: =変更履歴!$J$2 -> マスタコード体系／一覧 | BS2: =変更履歴!AU2 -> 45518 | BX2: =変更履歴!AZ2 | CC2: =変更履歴!BE2 -> 穆政道 | CI2: =変更履歴!BK2 -> 1
B3: 1.コードグループ一覧
C4: コード グループID | H4: コード分類名称 | V4: 体系 有無 | Y4: 説明 | BI4: 備考
C5: 101 | H5: 通信完了区分
C6: 102 | H6: 削除区分
C7: 103 | H7: 削除状態 | Y7: 「運用メッセージ履歴マスタ」「会社内メッセージ履歴マスタ」利用
C8: 104 | H8: 読み状態 | Y8: 「運用メッセージ履歴マスタ」「会社内メッセージ履歴マスタ」利用
C9: 105 | H9: APPバージョン状態 | Y9: 「APPバージョンマスタ」利用
C10: 106 | H10: 支払状態
C11: 107 | H11: 申込状態
C12: 108 | H12: 会社状態 | Y12: 「会社情報マスタ」利用
C13: 109 | H13: 帳票_区分
C14: 110 | H14: 帳票_方向
C15: 111 | H15: 位置 | Y15: 「帳票編集明细」利用
C16: 112 | H16: 分類 | Y16: 「帳票編集明细」利用
C17: 113 | H17: フィールド名を表示 | Y17: 「帳票編集明细」利用
C18: 114 | H18: ユーザー状態
C19: 115 | H19: アクション区分
C20: 116 | H20: ログレベル
C21: 117 | H21: 入荷状態
C22: 118 | H22: 連携済 | Y22: 検品済、入庫済、入荷確定、ピッキングリスト出力済、出庫済、梱包済、出荷確定同じコード
C23: 119 | H23: 取込エラーフラグ
C24: 120 | H24: 出荷状態
C25: 121 | H25: 納品書出力
C26: 122 | H26: 引当済
C27: 123 | H27: 入/出荷予定区分
C28: 124 | H28: 入出庫区分
C29: 125 | H29: 棚卸確定
C30: 126 | H30: 差異チェック
C31: 127 | H31: 完了チェック
C32: 128 | H32: 返品区分
C33: 129 | H33: 移動調整区分
C34: 130 | H34: 採番区分
C48: =IF(AND(G48="",I48="",K48=""),"","F"&TEXT(CO48,"00")&TEXT(CP48,"00")&TEXT(CQ48,"00"))
C49: =IF(AND(G49="",I49="",K49=""),"","F"&TEXT(CO49,"00")&TEXT(CP49,"00")&TEXT(CQ49,"00"))

Sheet マスタコード一覧
A1: ドキュメントID | N1: ドキュメント名称 | BS1: 作成日 | BX1: 更新日 | CC1: 更新者 | CI1: ﾊﾞｰｼﾞｮﾝ
A2: =変更履歴!$A$2 -> 0 | N2: =変更履歴!$J$2 -> マスタコード体系／一覧 | BS2: =変更履歴!AU2 -> 45518 | BX2: =変更履歴!AZ2 | CC2: =変更履歴!BE2 -> 穆政道 | CI2: =変更履歴!BK2 -> 1
B3: 2.マスタコード一覧
C4: コード グループID | H4: コード分類名称 | V4: コード値 | AC4: コード内容 | AS4: 桁数 | BI4: 並び順 | BM4: 備考
C5: 101 | H5: =IFERROR(VLOOKUP(C5,コードグループ一覧!$C$5:$U$37,6,FALSE),"") -> 通信完了区分 | V5: 1 | AC5: 完了 | AS5: 1 | BI5: 1
C6: 101 | H6: =IFERROR(VLOOKUP(C6,コードグループ一覧!$C$5:$U$37,6,FALSE),"") -> 通信完了区分 | V6: 2 | AC6: 未完了 | AS6: 1 | BI6: 2
C7: 102 | H7: =IFERROR(VLOOKUP(C7,コードグループ一覧!$C$5:$U$37,6,FALSE),"") -> 削除区分 | V7: 1 | AC7: 強制完了 | AS7: 1 | BI7: 1 | BM7: 削除済み
C8: 102 | H8: =IFERROR(VLOOKUP(C8,コードグループ一覧!$C$5:$U$37,6,FALSE),"") -> 削除区分 | V8: 2 | AC8: 未削除 | AS8: 1 | BI8: 2
C9: 103 | H9: =IFERROR(VLOOKUP(C9,コードグループ一覧!$C$5:$U$37,6,FALSE),"") -> 削除状態 | V9: 1 | AC9: 正常 | AS9: 1 | BI9: 1
C10: 103 | H10: =IFERROR(VLOOKUP(C10,コードグループ一覧!$C$5:$U$37,6,FALSE),"") -> 削除状態 | V10: 2 | AC10: 削除 | AS10: 1 | BI10: 2
C11: 104 | H11: =IFERROR(VLOOKUP(C11,コードグループ一覧!$C$5:$U$37,6,FALSE),"") -> 読み状態 | V11: 1 | AC11: 既読 | AS11: 1 | BI11: 1
C12: 104 | H12: =IFERROR(VLOOKUP(C12,コードグループ一覧!$C$5:$U$37,6,FALSE),"") -> 読み状態 | V12: 2 | AC12: 未読 | AS12: 1 | BI12: 2
C13: 105 | H13: =IFERROR(VLOOKUP(C13,コードグループ一覧!$C$5:$U$37,6,FALSE),"") -> APPバージョン状態 | V13: 1 | AC13: 公開 | AS13: 1 | BI13: 1
C14: 105 | H14: =IFERROR(VLOOKUP(C14,コードグループ一覧!$C$5:$U$37,6,FALSE),"") -> APPバージョン状態 | V14: 2 | AC14: 非公開 | AS14: 1 | BI14: 2
C15: 106 | H15: =IFERROR(VLOOKUP(C15,コードグループ一覧!$C$5:$U$37,6,FALSE),"") -> 支払状態 | V15: 0 | AC15: 未支払 | AS15: 1 | BI15: 1
C16: 106 | H16: =IFERROR(VLOOKUP(C16,コードグループ一覧!$C$5:$U$37,6,FALSE),"") -> 支払状態 | V16: 1 | AC16: 支払済み | AS16: 1 | BI16: 2
C17: 107 | H17: =IFERROR(VLOOKUP(C17,コードグループ一覧!$C$5:$U$37,6,FALSE),"") -> 申込状態 | V17: 0 | AC17: 未受付 | AS17: 1 | BI17: 1
C18: 107 | H18: =IFERROR(VLOOKUP(C18,コードグループ一覧!$C$5:$U$37,6,FALSE),"") -> 申込状態 | V18: 1 | AC18: 受付済み | AS18: 1 | BI18: 2
C19: 107 | H19: =IFERROR(VLOOKUP(C19,コードグループ一覧!$C$5:$U$37,6,FALSE),"") -> 申込状態 | V19: 2 | AC19: 却下 | AS19: 1 | BI19: 3
... C58: 115 | H58: =IFERROR(VLOOKUP(C58,コードグループ一覧!$C$5:$U$37,6,FALSE),"") -> アクション区分 | V58: 14 | AC58: 棚卸確定取消 | AS58: 1 | BI58: 14
C59: 116 | H59: =IFERROR(VLOOKUP(C59,コードグループ一覧!$C$5:$U$37,6,FALSE),"") -> ログレベル | V59: INFO | AC59: インフォ | AS59: 255 | BI59: 1
C60: 116 | H60: =IFERROR(VLOOKUP(C60,コードグループ一覧!$C$5:$U$37,6,FALSE),"") -> ログレベル | V60: WARN | AC60: 警告 | AS60: 255 | BI60: 2
C61: 116 | H61: =IFERROR(VLOOKUP(C61,コードグループ一覧!$C$5:$U$37,6,FALSE),"") -> ログレベル | V61: ERROR | AC61: エラー | AS61: 255 | BI61: 3
C62: 117 | H62: =IFERROR(VLOOKUP(C62,コードグループ一覧!$C$5:$U$37,6,FALSE),"") -> 入荷状態 | V62: 1 | AC62: 検品待ち | AS62: 1 | BI62: 1
C63: 117 | H63: =IFERROR(VLOOKUP(C63,コードグループ一覧!$C$5:$U$37,6,FALSE),"") -> 入荷状態 | V63: 2 | AC63: 入庫待ち | AS63: 1 | BI63: 2
C64: 117 | H64: =IFERROR(VLOOKUP(C64,コードグループ一覧!$C$5:$U$37,6,FALSE),"") -> 入荷状態 | V64: 3 | AC64: 入庫中 | AS64: 1 | BI64: 3
C65: 117 | H65: =IFERROR(VLOOKUP(C65,コードグループ一覧!$C$5:$U$37,6,FALSE),"") -> 入荷状態 | V65: 4 | AC65: 入荷確定待ち | AS65: 1 | BI65: 4
C66: 117 | H66: =IFERROR(VLOOKUP(C66,コードグループ一覧!$C$5:$U$37,6,FALSE),"") -> 入荷状態 | V66: 5 | AC66: 入荷済み | AS66: 1 | BI66: 5
C67: 118 | H67: =IFERROR(VLOOKUP(C67,コードグループ一覧!$C$5:$U$37,6,FALSE),"") -> 連携済 | V67: 1 | AC67: ON | AS67: 1 | BI67: 1 | BM67: 連携済
C68: 118 | H68: =IFERROR(VLOOKUP(C68,コードグループ一覧!$C$5:$U$37,6,FALSE),"") -> 連携済 | V68: 2 | AC68: OFF(default) | AS68: 1 | BI68: 2 | BM68: 未連携
C69: 119 | H69: =IFERROR(VLOOKUP(C69,コードグループ一覧!$C$5:$U$37,6,FALSE),"") -> 取込エラーフラグ | V69: 1 | AC69: 導入された商品IDは存在しません | AS69: 1 | BI69: 1
C70: 119 | H70: =IFERROR(VLOOKUP(C70,コードグループ一覧!$C$5:$U$37,6,FALSE),"") -> 取込エラーフラグ | V70: 2 | AC70: インポート時にエラーが発生しました | AS70: 1 | BI70: 2
C71: 119 | H71: =IFERROR(VLOOKUP(C71,コードグループ一覧!$C$5:$U$37,6,FALSE),"") -> 取込エラーフラグ | V71: 3 | AC71: マスターテーブルのインポート中にエラーが発生しました | AS71: 1 | BI71: 3
C72: 119 | H72: =IFERROR(VLOOKUP(C72,コードグループ一覧!$C$5:$U$37,6,FALSE),"") -> 取込エラーフラグ | V72: 4 | AC72: サブテーブルのインポート中にエラーが発生しました | AS72: 1 | BI72: 4
C73: 119 | H73: =IFERROR(VLOOKUP(C73,コードグループ一覧!$C$5:$U$37,6,FALSE),"") -> 取込エラーフラグ | V73: 5 | AC73: インポートされたフィールドの数またはタイプが一致しません | AS73: 1 | BI73: 5
C74: 120 | H74: =IFERROR(VLOOKUP(C74,コードグループ一覧!$C$5:$U$37,6,FALSE),"") -> 出荷状態 | V74: 0 | AC74: 引当失敗 | AS74: 1 | BI74: 1
C75: 120 | H75: =IFERROR(VLOOKUP(C75,コードグループ一覧!$C$5:$U$37,6,FALSE),"") -> 出荷状態 | V75: 1 | AC75: 引当待ち | AS75: 1 | BI75: 2
C76: 120 | H76: =IFERROR(VLOOKUP(C76,コードグループ一覧!$C$5:$U$37,6,FALSE),"") -> 出荷状態 | V76: 2 | AC76: 出庫待ち | AS76: 1 | BI76: 3
C77: 120 | H77: =IFERROR(VLOOKUP(C77,コードグループ一覧!$C$5:$U$37,6,FALSE),"") -> 出荷状態 | V77: 3 | AC77: 出庫中 | AS77: 1 | BI77: 4
C78: 120 | H78: =IFERROR(VLOOKUP(C78,コードグループ一覧!$C$5:$U$37,6,FALSE),"") -> 出荷状態 | V78: 4 | AC78: 検品待ち | AS78: 1 | BI78: 5
...

Sheet コード体系
A1: ドキュメントID | N1: ドキュメント名称 | BS1: 作成日 | BX1: 更新日 | CC1: 更新者 | CI1: ﾊﾞｰｼﾞｮﾝ
A2: =変更履歴!$A$2 -> 0 | N2: =変更履歴!$J$2 -> マスタコード体系／一覧 | BS2: =変更履歴!AU2 -> 45518 | BX2: =変更履歴!AZ2 | CC2: =変更履歴!BE2 -> 穆政道 | CI2: =変更履歴!BK2 -> 1
B3: 3.コード体系
D4: 1.オーダー番号
E5: 固定文言 | Q5: システム日付 | AY5: 4桁乱数
E6: 1 | Q6: 2 | AY6: 3
E7: O | G7: R | I7: D | K7: E | M7: R | O7: _ | Q7: Y | S7: Y | U7: Y | W7: Y | Y7: M | AA7: M | AC7: D | AE7: D | AG7: H | AI7: H | AK7: m | AM7: m | AO7: s | AQ7: s | AS7: ms | AU7: ms | AW7: ms | AY7: 9 | BA7: 9 | BC7: 9 | BE7: 9
E9: No | G9: 内容 | X9: 備考
E10: 1 | G10: 固定文言
E11: 2 | G11: システム日付を設定
E12: 3 | G12: "0000"～"9999"の4桁乱数 | X12: 先頭ゼロ埋め４桁とする
D14: 2.ロケーションコード
E15: 倉庫略称 | K15: 区分 | O15: ゾーン | U15: 列＊ | AA15: 棚＊ | AG15: 段＊ | AM15: ＊区分はSの場合、表示
E16: 1 | K16: 2 | O16: 3 | U16: 4 | AA16: 5 | AG16: 6
E17: X | I17: - | K17: X | M17: - | O17: X | S17: - | U17: X | Y17: - | AA17: X | AE17: - | AG17: X
E19: No | G19: 内容 | X19: 備考
E20: 1 | G20: 倉庫略称
E21: 2 | G21: 区分 | X21: 棚(S)、カゴ車またはオリコン(C)、箱（段ボール）(B)
E22: 3 | G22: ゾーン | X22: 例：A1,B1,C1,D1,E1
E23: 4 | G23: 列 | X23: 例：A,B,C,D,E
E24: 5 | G24: 棚 | X24: 例：01,02,03,04,05
E25: 6 | G25: 段 | X25: 例：1,2,3,4,5
D27: 3.入荷予定番号/出荷指示番号
E28: 会社略称 | O28: 採番区分 | S28: システム日付 | AG28: 連番
E29: 1 | O29: 2 | S29: 3 | AG29: 4
E30: X | G30: X | I30: X | K30: X | M30: - | O30: X | Q30: - | S30: Y | U30: Y | W30: Y | Y30: Y | AA30: M | AC30: M | AE30: - | AG30: 9 | AI30: 9 | AK30: 9 | AM30: 9 | AO30: 9 | AQ30: 9 | AS30: 9 | AU30: 9
E33: No | G33: 内容 | X33: 備考
E34: 1 | G34: 会社略称
E35: 2 | G35: 採番区分 | X35: 入荷:A 出荷:B
E36: 3 | G36: システム日付 | X36: 年月
E37: 4 | G37: 連番 | X37: 8桁、テーブル「mtb_number(採番マスタ)」より取得
D39: 4.入荷予定明細行No/出荷指示明細行No
E40: 入荷予定番号/出荷指示番号 | M40: 連番*
E41: XXXXXXX | M41: 9 | O41: 9 | Q41: 9
W42: * 001 ～ "999" までの番号とする（必ず3桁とする）
D44: 5.ピッキング明細行No
E45: 入荷予定明細行No | O45: 連番*
E46: XXXXXXX | M46: - | O46: 9 | Q46: 9 | S46: 9
W47: * 001 ～ "999" までの番号とする（必ず3桁とする）
