Workbook
Name ｓｓｓ: #REF!
Name WEBフロント画面ロール: #REF!
Name ドメインコード: [1]区分値!$J$4:$J$110
Name ドメインコード: #REF!
Name 画面部品種類: [1]区分値!$B$4:$B$26
Name 画面部品種類: #REF!
Name 画面部品種類1: [2]区分値!$B$4:$B$26
Name 管理画面ロール: #REF!
Name 検索条件区分: [1]区分値!$Z$3:$Z$22
Name 検索条件区分: #REF!
Name 条件付き必須チェック条件式: [1]区分値!$AH$3:$AH$10
Name 条件付き必須チェック条件式: #REF!

Sheet version
A1: プロジェクト名 | P1: 資料分類 | AE1: 資料小分類 | BC1: 作成 | BG1: 担当
BG2: 日付
A3: システム名 | P3: 画面ID | AE3: 画面名 | BC3: 修正 | BG3: 担当
BG4: 日付
D7: 更新日 | M7: Ver | R7: 更新者 | Z7: 更新箇所（シート） | AK7: 更新内容 | BM7: 承認者

Sheet 画面レイアウト
A1: プロジェクト名 | G1: =IF(version!G1<>"",version!G1,"") | P1: 資料分類 | V1: =IF(version!V1<>"",version!V1,"") | AE1: 資料小分類 | AK1: =IF(version!AK1<>"",version!AK1,"") | BC1: 作成 | BG1: 担当 | BK1: =IF(version!BK1<>"",version!BK1,"")
BG2: 日付 | BK2: =IF(version!BK2<>"",version!BK2,"")
A3: システム名 | G3: =IF(version!G3<>"",version!G3,"") | P3: 画面ID | V3: =IF(version!V3<>"",version!V3,"") | AE3: 画面名 | AK3: =IF(version!AK3<>"",version!AK3,"") | BC3: 修正 | BG3: 担当 | BK3: =IF(version!BK3<>"",version!BK3,"")
BG4: 日付 | BK4: =IF(version!BK4<>"",version!BK4,"")
B6: 画面レイアウト
E9: 画面ID | L9: =V3 | W9: 画面名 | AA9: =AK3
E10: 概要
E13: 利用者
E15: 動的項目一覧
E16: No | G16: 名称 | P16: 一覧表示形式 | Y16: 件数 | AK16: ソート順 | AP16: 備考
Y17: デフォルト | AC17: 最小 | AG17: 最大
E18: 1 | G18: 設定ルール | P18: 全件表示 | Y18: - | AC18: 0 | AG18: - | AK18: -
E19: 2 | G19: アクション | P19: 全件表示 | Y19: - | AC19: 0 | AG19: - | AK19: -
E20: 3 | G20: 操作 | P20: 全件表示 | Y20: - | AC20: 0 | AG20: - | AK20: -
E21: 4 | Y21: - | AC21: - | AG21: - | AK21: -
E22: 5 | Y22: - | AC22: - | AG22: - | AK22: -
E25: http/https | L25: 3:http/https両方 | S25: メソッド | AA25: -
E26: パラメータ | L26: ﾊﾟﾗﾒｰﾀ名(英語) | S26: ﾊﾟﾗﾒｰﾀ名(日本語) | AA26: 説明
S27: お問い合わせ番号 | AA27: 前画面からお問い合わせ番号を受け取った際、その番号に対応する一覧を表示する。
L33: EOF

Sheet 画面入出力項目
A1: プロジェクト名 | G1: =IF(version!G1<>"",version!G1,"") | P1: 資料分類 | V1: =IF(version!V1<>"",version!V1,"") | AE1: 資料小分類 | AK1: =IF(version!AK1<>"",version!AK1,"") | BF1: 作成 | BJ1: 担当 | BN1: =IF(version!BK1<>"",version!BK1,"")
BJ2: 日付 | BN2: =IF(version!BK2<>"",version!BK2,"")
A3: システム名 | G3: =IF(version!G3<>"",version!G3,"") | P3: 画面ID | V3: =IF(version!V3<>"",version!V3,"") | AE3: 画面名 | AK3: =IF(version!AK3<>"",version!AK3,"") | BF3: 修正 | BJ3: 担当 | BN3: =IF(version!BK3<>"",version!BK3,"")
BJ4: 日付 | BN4: =IF(version!BK4<>"",version!BK4,"")
B6: 画面入出力項目
B7: 1.画面入出力項目
B8: 番号 | D8: エリア | J8: 表示項目名称 | Q8: 画面部品種類 | T8: 入力 | U8: ドメイン定義 (ドメインコード：ドメイン名) | AD8: 桁数 | AF8: 必須 | AG8: 初期表示内容 | AM8: 実行API 項目 | AS8: 出力仕様 | AZ8: 権限仕様 | BI8: 補足
B9: 1 | D9: パンくずリストエリア | T9: - | U9: -- | AZ9: --
B10: 1-1
B11: 1-2
B12: 1-3
B13: 1-4
B14: 2 | D14: ヘッダエリア
B15: 2-1
B16: 2-2
B17: 3 | D17: 一覧ヘッダエリア
B18: 1
B19: 2
B20: 4 | D20: 承認ルール一覧エリア
B21: 1
B22: 2
B23: 3
B24: 7
B25: 8
B26: 9
B27: 10
B28: 4
B29: 5
B30: 6
B31: 5 | D31: メール設定の変更エリア
B32: 1
B33: 2
B34: 3
B35: 4
B37: 2.条件付き必須チェック
B38: 番号 | D38: 必須チェック項目名称 | K38: 条件項目名称 | R38: 条件式 | V38: 条件値 | AC38: メッセージID
R39: -- | AC39: -
R40: -- | AC40: -
B41: 999
B43: 3.項目間相関関係
...

Sheet 画面アクション
A1: プロジェクト名 | G1: =IF(version!G1<>"",version!G1,"") | P1: 資料分類 | V1: =IF(version!V1<>"",version!V1,"") | AE1: 資料小分類 | AK1: =IF(version!AK1<>"",version!AK1,"") | BC1: 作成 | BG1: 担当 | BK1: =IF(version!BK1<>"",version!BK1,"")
BG2: 日付 | BK2: =IF(version!BK2<>"",version!BK2,"")
A3: システム名 | G3: =IF(version!G3<>"",version!G3,"") | P3: 画面ID | V3: =IF(version!V3<>"",version!V3,"") | AE3: 画面名 | AK3: =IF(version!AK3<>"",version!AK3,"") | BC3: 修正 | BG3: 担当 | BK3: =IF(version!BK3<>"",version!BK3,"")
BG4: 日付 | BK4: =IF(version!BK4<>"",version!BK4,"")
B6: 画面アクション
B8: アクションID | F8: アクション名 | K8: アクション概要 | S8: 順序 | U8: アクション詳細 | AY8: 遷移先画面 | BD8: エラー時遷移先 | BI8: メッセージID | BM8: メッセージ引数
B9: 1 | F9: インデックス | K9: 初期チェック | S9: 1
S10: 2
S11: 3
K12: 部門管理権限ユーザ情報取得 | S12: 3
K13: 部門一覧取得 | S13: 4
K14: 部門設定切り替えプルダウンの設定 | S14: 5
S15: 6
K16: 承認WF利用設定情報取得 | S16: 7
K17: 承認WF情報取得 | S17: 8
K18: 承認経路情報取得 | S18: 9
S19: 10
S20: 11
S21: 12
K22: 初期表示 | S22: 13
S23: 14
B24: 2 | F24: 「ASKULホーム」リンクをクリック | K24: TOP画面へ遷移 | S24: 1
B25: 3 | F25: 「管理権限ユーザメニュー」リンクをクリック | K25: 組織メニュートップ画面へ遷移 | S25: 1
B26: 4 | F26: 「承認ワークフローの管理」リンクをクリック | K26: 承認ワークフロートップ（企業サマリ・部門一覧）画面へ遷移 | S26: 1
B27: 5 | F27: 「承認ルール一覧」リンクをクリック | K27: ワークフロー設定一覧（企業標準・部門別）画面へ遷移 | S27: 1
B28: 6 | F28: 「部門設定切り替え」プルダウンを選択 | K28: 設定する部門・あるいは企業標準設定の選択 | S28: 1
B29: 7 | F29: 「部門一覧から検索する」リンクをクリック | K29: 承認ワークフロー設定 登録・変更（全画面モーダル）を表示 | S29: 1
B30: 8 | F30: 「ワークフロー新規登録」ボタンをクリック | K30: 承認ワークフロー設定 登録・変更（全画面モーダル）を表示 | S30: 1
B31: 9 | F31: 「編集」リンククリック | K31: 編集 | S31: 1
B32: 10 | F32: 「削除」リンククリック | K32: 削除 | S32: 1
S33: 1
S34: 2
S35: 3
S36: 4
S37: 5
B38: 11 | F38: 「メール設定変更」ボタンをクリック | K38: メール送信設定（全画面モーダル）を表示 | S38: 1
